Traceback (most recent call last):
  File "/opt/anaconda3/envs/FDTD/lib/python3.7/site-packages/jupyter_cache/executors/utils.py", line 56, in single_nb_execution
    record_timing=False,
  File "/opt/anaconda3/envs/FDTD/lib/python3.7/site-packages/nbclient/client.py", line 1117, in execute
    return NotebookClient(nb=nb, resources=resources, km=km, **kwargs).execute()
  File "/opt/anaconda3/envs/FDTD/lib/python3.7/site-packages/nbclient/util.py", line 78, in wrapped
    return just_run(coro(*args, **kwargs))
  File "/opt/anaconda3/envs/FDTD/lib/python3.7/site-packages/nbclient/util.py", line 57, in just_run
    return loop.run_until_complete(coro)
  File "/opt/anaconda3/envs/FDTD/lib/python3.7/asyncio/base_events.py", line 587, in run_until_complete
    return future.result()
  File "/opt/anaconda3/envs/FDTD/lib/python3.7/site-packages/nbclient/client.py", line 559, in async_execute
    cell, index, execution_count=self.code_cells_executed + 1
  File "/opt/anaconda3/envs/FDTD/lib/python3.7/site-packages/nbclient/client.py", line 862, in async_execute_cell
    self._check_raise_for_error(cell, exec_reply)
  File "/opt/anaconda3/envs/FDTD/lib/python3.7/site-packages/nbclient/client.py", line 765, in _check_raise_for_error
    raise CellExecutionError.from_cell_and_msg(cell, exec_reply_content)
nbclient.exceptions.CellExecutionError: An error occurred while executing the following cell:
------------------
# load the baby weight data
babyweight <-read.csv('~/shared/data/babyweight.csv')
#extract the data for babys whose mothers smoked
babyweight_smoking <- filter(babyweight, Smoke=='yes')

# create a scatter plot of getational time and birth weight
ggplot(babyweight_smoking, aes(x=Gest, y=Wgt)) + 
    geom_point() + 
    scale_x_continuous(breaks = 32:42) +
    scale_y_continuous(breaks = seq(2400, 3600, 100)) +
    xlab('Length of Gestation (weeks)') +
    ylab('Birth Weight (g)') +
    labs(title = 'Babies born to mothers who smoked') +
    theme_classic() +
    theme(panel.grid.major = element_line(color = "grey50"))
------------------

Error in file(file, "rt"): cannot open the connection
Traceback:

1. read.csv("~/shared/data/babyweight.csv")
2. read.table(file = file, header = header, sep = sep, quote = quote, 
 .     dec = dec, fill = fill, comment.char = comment.char, ...)
3. file(file, "rt")
ERROR: Error in file(file, "rt"): cannot open the connection


