Traceback (most recent call last):
  File "/home/corrin/miniconda3/envs/book/lib/python3.8/site-packages/jupyter_cache/executors/utils.py", line 51, in single_nb_execution
    executenb(
  File "/home/corrin/miniconda3/envs/book/lib/python3.8/site-packages/nbclient/client.py", line 1093, in execute
    return NotebookClient(nb=nb, resources=resources, km=km, **kwargs).execute()
  File "/home/corrin/miniconda3/envs/book/lib/python3.8/site-packages/nbclient/util.py", line 84, in wrapped
    return just_run(coro(*args, **kwargs))
  File "/home/corrin/miniconda3/envs/book/lib/python3.8/site-packages/nbclient/util.py", line 62, in just_run
    return loop.run_until_complete(coro)
  File "/home/corrin/miniconda3/envs/book/lib/python3.8/asyncio/base_events.py", line 616, in run_until_complete
    return future.result()
  File "/home/corrin/miniconda3/envs/book/lib/python3.8/site-packages/nbclient/client.py", line 559, in async_execute
    await self.async_execute_cell(
  File "/home/corrin/miniconda3/envs/book/lib/python3.8/site-packages/nbclient/client.py", line 854, in async_execute_cell
    self._check_raise_for_error(cell, exec_reply)
  File "/home/corrin/miniconda3/envs/book/lib/python3.8/site-packages/nbclient/client.py", line 756, in _check_raise_for_error
    raise CellExecutionError.from_cell_and_msg(cell, exec_reply_content)
nbclient.exceptions.CellExecutionError: An error occurred while executing the following cell:
------------------
nyc_dogs <- read.csv('~/shared/data/NYC_Dog_Licensing.csv')  # add the final name and path in quotes
library('dplyr') # load the dplyr package

nyc_dogs <- mutate(nyc_dogs, Age = 2021 - AnimalBirthYear) # age is approximately current_year - birth_year
head(nyc_dogs) # view the results
------------------

Error in file(file, "rt"): cannot open the connection
Traceback:

1. read.csv("~/shared/data/NYC_Dog_Licensing.csv")
2. read.table(file = file, header = header, sep = sep, quote = quote, 
 .     dec = dec, fill = fill, comment.char = comment.char, ...)
3. file(file, "rt")
ERROR: Error in file(file, "rt"): cannot open the connection


